Workbook

Sheet Mechanical
A1: ENGG.tv Contents
A3: Subject | B3: Chapters | C3: Topics | D3: Video Notes | E3: Theory Questions | F3: Numericals | G3: Vid Explanation | H3: Homework/Solution
A4: Mathematics | B4: Math Basics | C4: Trigonometry | D4: 3 | E4: 5 | F4: 6 | G4: 0 | H4: 1
C5: Logarithms | D5: 0 | E5: 4 | F5: 5 | G5: 0 | H5: 1
C6: Areas and Volumes | D6: 0 | E6: 0 | F6: 5 | G6: 0 | H6: 1
C7: Theory of Complex Numbers | D7: 0 | E7: 6 | F7: 5 | G7: 0 | H7: 0
C8: Calculators | D8: 0 | E8: 0 | F8: 2 | G8: 0 | H8: 0
B9: Analytic Geometry | C9: Straight Lines | D9: 1 | E9: 6 | F9: 8 | G9: 3 | H9: 1
C10: Conics | D10: 1 | E10: 2 | F10: 5 | G10: 0 | H10: 0
C11: Circles | D11: 2 | E11: 4 | F11: 9 | G11: 2 | H11: 1
C13: Ellipse | D13: 1 | E13: 2 | F13: 5 | G13: 1 | H13: 1
C14: Parabola | D14: 1 | E14: 3 | F14: 7 | G14: 0 | H14: 1
C15: Hyperbola | D15: 1 | E15: 2 | F15: 6 | G15: 1 | H15: 1
B16: Calculus | C16: Limits | D16: 1 | E16: 5 | F16: 5 | G16: 1 | H16: 1
C17: Derivative | D17: 1 | E17: 2 | F17: 5 | G17: 0 | H17: 1
C18: Application of Derivatives | D18: 2 | E18: 6 | F18: 5 | G18: 0 | H18: 1
C19: Partial Derivatives | D19: 0 | E19: 3 | F19: 2 | G19: 1 | H19: 1
C20: Indefinite Integrals | D20: 1 | E20: 0 | F20: 5 | G20: 0 | H20: 0
B21: Differential Equations | C21: General Terminology | D21: 1 | E21: 5 | F21: 0 | G21: 0 | H21: 0
C22: First Order DE | D22: 1 | E22: 2 | F22: 7 | G22: 0 | H22: 0
C23: Higher Order DE | D23: 4 | E23: 0 | F23: 5 | G23: 1 | H23: 1
C24: Laplace Transform | D24: 1 | E24: 3 | F24: 5 | G24: 1 | H24: 1
B25: Linear Algebra | C25: Determinant of a Matrix | D25: 0 | E25: 3 | F25: 2 | G25: 0 | H25: 0
C27: Matrix Operations | D27: 0 | E27: 2 | F27: 5 | G27: 0 | H27: 0
C28: Unit Vector | D28: 1 | E28: 6 | F28: 6 | G28: 0 | H28: 0
C29: Dot and Cross Products | D29: 2 | E29: 5 | F29: 7 | G29: 1 | H29: 0
C30: Gradient, Divergence and Curl | D30: 1 | E30: 2 | F30: 8 | G30: 0 | H30: 1
B33: Numerical Methods | C33: Newton’s Method of Root Extraction | D33: 1 | E33: 2 | F33: 5 | G33: 0 | H33: 1
C34: Newton’s Method of Minimization | D34: 0 | E34: 0 | F34: 2 | G34: 0 | H34: 0
C35: Forward Rectangle Rule | D35: 1 | E35: 2 | F35: 2 | G35: 0 | H35: 1
C36: Trapezoidal Rule | D36: 1 | E36: 2 | F36: 5 | G36: 1 | H36: 1
C37: Simpson’s Rule | D37: 0 | E37: 0 | F37: 3 | G37: 0 | H37: 0
C38: Taylor’s and McLaurin’s Series | D38: 0 | E38: 0 | F38: 2 | G38: 0 | H38: 1
B39: Algorithm and Logic Development | C39: Flowchart | D39: 1 | E39: 4 | F39: 0 | G39: 0 | H39: 1
C40: Pseudocode | D40: 0 | E40: 5 | F40: 1 | G40: 0 | H40: 0
A41: Probability and Statistics | B41: Measures of Central Tendencies and Distribution | C41: Mean, Median Mode | D41: 1 | E41: 7 | F41: 8 | G41: 0 | H41: 1
C42: Standard Deviation and Variance | D42: 0 | E42: 3 | F42: 5 | G42: 0 | H42: 0
B43: Permutations and Combinations | C43: Arrangement and Selection | D43: 1 | E43: 2 | F43: 5 | G43: 0 | H43: 0
C44: Selection with Identical Objects | D44: 0 | E44: 0 | F44: 3 | G44: 0 | H44: 0
B45: Laws of Probability | C45: Probability Concepts | D45: 1 | E45: 5 | F45: 10 | G45: 0 | H45: 1
...

Sheet Other
A1: ENGG.tv Contents
A3: Subject | B3: Chapters | C3: Topics | D3: Video Notes | E3: Theory Questions | F3: Numericals | G3: Vid Explanation | H3: Homework/Solution
A4: Mathematics | B4: Math Basics | C4: Trigonometry | D4: ='Mechanical'!D4 -> 3 | E4: ='Mechanical'!E4 -> 5 | F4: ='Mechanical'!F4 -> 6 | G4: ='Mechanical'!G4 -> 0 | H4: ='Mechanical'!H4 -> 1
C5: Logarithms | D5: 0 | E5: 2 | F5: 3 | G5: 0 | H5: 1
C6: Areas and Volumes | D6: ='Mechanical'!D6 -> 0 | E6: ='Mechanical'!E6 -> 0 | F6: ='Mechanical'!F6 -> 5 | G6: ='Mechanical'!G6 -> 0 | H6: ='Mechanical'!H6 -> 1
C7: Theory of Complex Numbers | D7: ='Mechanical'!D7 -> 0 | E7: ='Mechanical'!E7 -> 6 | F7: ='Mechanical'!F7 -> 5 | G7: ='Mechanical'!G7 -> 0 | H7: ='Mechanical'!H7 -> 0
C8: Calculators | D8: ='Mechanical'!D8 -> 0 | E8: ='Mechanical'!E8 -> 0 | F8: ='Mechanical'!F8 -> 2 | G8: ='Mechanical'!G8 -> 0 | H8: ='Mechanical'!H8 -> 0
B9: Analytic Geometry | C9: Straight Line | D9: 1 | E9: ='Mechanical'!E9 -> 6 | F9: 8 | G9: 3 | H9: 1
C10: Conics | D10: 1 | E10: ='Mechanical'!E10 -> 2 | F10: 3 | G10: 0 | H10: 0
C11: Circle | D11: ='Mechanical'!D11 -> 2 | E11: 1 | F11: 9 | G11: 2 | H11: 1
C12: Ellipse | D12: ='Mechanical'!D13 -> 1 | E12: ='Mechanical'!E13 -> 2 | F12: ='Mechanical'!F13 -> 5 | G12: ='Mechanical'!G13 -> 1 | H12: ='Mechanical'!H13 -> 1
C13: Parabola | D13: 1 | E13: 2 | F13: 8 | G13: 0 | H13: 1
C14: Hyperbola | D14: 1 | E14: 2 | F14: 6 | G14: 1 | H14: 1
B15: Linear Algebra | C15: Determinant of a Matrix | D15: 0 | E15: 1 | F15: 2 | G15: 0 | H15: 0
C16: Matrix Operations | D16: 0 | E16: 2 | F16: 7 | G16: 0 | H16: 0
B17: Differential Equations | C17: General Terminology | D17: 1 | E17: 4 | F17: 0 | G17: 0 | H17: 0
C18: First Order DE | D18: 1 | E18: 2 | F18: 7 | G18: 0 | H18: 0
C19: Higher Order DE | D19: 4 | E19: 0 | F19: 3 | G19: 1 | H19: 0
B20: Numerical Methods | C20: Newton’s Method of Root Extraction | D20: 1 | E20: 2 | F20: 3 | G20: 0 | H20: 1
C21: Newton’s Method of Minimization | D21: 0 | E21: 0 | F21: 2 | G21: 0 | H21: 0
C22: Forward Rectangle Rule | D22: 1 | E22: 2 | F22: 2 | G22: 0 | H22: 1
C23: Trapezoidal Rule | D23: 1 | E23: 2 | F23: 4 | G23: 1 | H23: 1
C24: Simpson’s Rule | D24: 0 | E24: 0 | F24: 2 | G24: 0 | H24: 0
C25: Taylor’s and McLaurin’s Series | D25: 0 | E25: 0 | F25: 2 | G25: 0 | H25: 1
B26: Single Variable Calculus | C26: Limits | D26: 0 | E26: 2 | F26: 2 | G26: 0 | H26: 1
C27: Derivative | D27: 1 | E27: 2 | F27: 3 | G27: 0 | H27: 1
C28: Application of Derivatives | D28: 0 | E28: 3 | F28: 0 | G28: 0 | H28: 1
C29: Indefinite Integrals | D29: 1 | E29: 0 | F29: 6 | G29: 0 | H29: 0
A30: Probability and Statistics | B30: Measures of Central Tendencies and Distribution | C30: Mean, Median Mode | D30: 1 | E30: 3 | F30: 9 | G30: 0 | H30: 1
C31: Standard Deviation | D31: 0 | E31: 3 | F31: 3 | G31: 0 | H31: 0
B32: Permutations and Combinations | C32: Arrangements and Selections | D32: 1 | E32: 2 | F32: 5 | G32: 0 | H32: 0
C33: Selection with Identical Objects | D33: 0 | E33: 0 | F33: 3 | G33: 0 | H33: 0
B34: Laws of Probability | C34: Probability Concepts | D34: 1 | E34: 2 | F34: 10 | G34: 0 | H34: 1
B35: Probability Functions, Distributions and Expected Values | C35: PDF and CDF | D35: 1 | E35: 2 | F35: 3 | G35: 1 | H35: 0
C36: Binomial Distribution | D36: 1 | E36: 1 | F36: 6 | G36: 1 | H36: 1
C37: Normal Distribution | D37: 1 | E37: 2 | F37: 4 | G37: 0 | H37: 1
C38: t-distribution | D38: 1 | E38: 2 | F38: 3 | G38: 0 | H38: 0
C39: Expected Value | D39: 0 | E39: 2 | F39: 4 | G39: 0 | H39: 0
B40: Propagation of Error | C40: Measurement of Error | D40: 0 | E40: 6 | F40: 0 | G40: 0 | H40: 0
C41: Linear Combinations | D41: 0 | E41: 0 | F41: 2 | G41: 0 | H41: 0
...

Sheet Civil
A1: ENGG.tv Contents
A3: Subject | B3: Chapters | C3: Topics | D3: Video Notes | E3: Theory Questions | F3: Numericals | G3: Vid Explanation | H3: Homework/Solution
A4: Mathematics and Statistics | B4: Math Basics | C4: Logarithms | D4: 0 | E4: 2 | F4: 3 | G4: 0 | H4: 1
C5: Areas and Volumes | D5: 0 | E5: 0 | F5: 4 | G5: 0 | H5: 1
C6: Calculators | D6: 0 | E6: 0 | F6: 2 | G6: 0 | H6: 0
B7: Analytic Geometry | C7: Straight Lines | D7: 1 | E7: 6 | F7: 8 | G7: 3 | H7: 1
C8: Conics | D8: 1 | E8: 2 | F8: 3 | G8: 0 | H8: 0
C9: Circle | D9: 2 | E9: 2 | F9: 14 | G9: 2 | H9: 1
C10: Ellipse | D10: 1 | E10: 2 | F10: 5 | G10: 1 | H10: 1
C11: Parabola | D11: 1 | E11: 2 | F11: 8 | G11: 0 | H11: 1
C12: Hyperbola | D12: 1 | E12: 2 | F12: 7 | G12: 1 | H12: 1
B13: Single-Variable Calculus | C13: Limits | D13: 0 | E13: 2 | F13: 2 | G13: 0 | H13: 1
C14: Derivative | D14: 1 | E14: 4 | F14: 0 | G14: 0 | H14: 1
C15: Application of Derivatives | D15: 0 | E15: 3 | F15: 0 | G15: 0 | H15: 1
C16: Indefinite Integrals | D16: 1 | E16: 0 | F16: 6 | G16: 0 | H16: 0
C17: Definite Integrals | D17: 1 | E17: 5 | F17: 0 | G17: 0 | H17: 1
B18: Vector Operations | C18: Unit Vector | D18: 1 | E18: 4 | F18: 5 | G18: 0 | H18: 0
C19: Dot and Cross Products | D19: 2 | E19: 10 | F19: 0 | G19: 1 | H19: 0
B20: Statistics | C20: Probability- Basic Concepts | D20: 2 | E20: 8 | F20: 0 | G20: 0 | H20: 1
C21: Binomial Distribution | D21: 1 | E21: 6 | F21: 0 | G21: 1 | H21: 1
C22: Normal Distribution | D22: 0 | E22: 4 | F22: 0 | G22: 0 | H22: 1
C23: t-distribution | D23: 0 | E23: 4 | F23: 0 | G23: 0 | H23: 0
C24: Mean, Median, Mode | D24: 0 | E24: 6 | F24: 0 | G24: 0 | H24: 1
C25: Standard Deviation and Variance | D25: 0 | E25: 4 | F25: 0 | G25: 0 | H25: 0
C26: Regression and Curve Fitting | D26: 1 | E26: 8 | F26: 0 | G26: 0 | H26: 0
A27: Ethics and Professional Practice | B27: Codes of Ethics | C27: NCEES Model Law | D27: 0 | E27: 11 | F27: 0 | G27: 0 | H27: 0
C28: Professional and Technical Societies | D28: 0 | E28: 6 | F28: 0 | G28: 0 | H28: 0
C29: Ethical and Legal Considerations | D29: 0 | E29: 18 | F29: 0 | G29: 0 | H29: 0
B30: Public Health, Safety and Welfare | C30: Public Health, Safety and Welfare in Engineering | D30: 0 | E30: 5 | F30: 0 | G30: 0 | H30: 0
B31: Licensure | C31: Licensure | D31: 1 | E31: 1 | F31: 0 | G31: 0 | H31: 0
B32: Contracts and Contract Law | C32: Agreements and Contract | D32: 0 | E32: 4 | F32: 0 | G32: 0 | H32: 0
A33: Engineering Economics | B33: Time Value of Money | C33: Time Value of Money | D33: 1 | E33: 2 | F33: 7 | G33: 1 | H33: 1
B34: Non-Annual Compounding | C34: Non-Annual Compounding | D34: 0 | E34: 2 | F34: 3 | G34: 0 | H34: 1
B35: Break-Even Analysis | C35: Break-Even Analysis | D35: 1 | E35: 11 | F35: 3 | G35: 0 | H35: 0
B36: Inflation | C36: Inflation | D36: 0 | E36: 3 | F36: 2 | G36: 0 | H36: 0
B37: Depreciation | C37: Depreciation | D37: 1 | E37: 3 | F37: 6 | G37: 0 | H37: 0
B38: Capitalized Cost | C38: Capitalized Cost | D38: 0 | E38: 3 | F38: 2 | G38: 0 | H38: 1
B39: Rate of Return | C39: Internal Rate of Return | D39: 0 | E39: 3 | F39: 3 | G39: 0 | H39: 0
B40: Benefit-Cost Analysis | C40: Benefit-Cost Analysis | D40: 0 | E40: 2 | F40: 2 | G40: 0 | H40: 0
B41: Decision Trees | C41: Decision Trees | D41: 0 | E41: 4 | F41: 2 | G41: 0 | H41: 0
...

Sheet Summary
B2: ENGG.tv Status for Various Disciplines (As on May 15, 2024)
C3: Civil | D3: Other | E3: Mechanical
B4: Chapters | C4: ='Civil'!J267 -> 73 | D4: ='Other'!J323 -> 95 | E4: ='Mechanical'!J369 -> 117
B5: Topics | C5: ='Civil'!K267 -> 245 | D5: ='Other'!K323 -> 301 | E5: ='Mechanical'!K369 -> 339
B6: Video Notes | C6: ='Civil'!L267 -> 41 | D6: ='Other'!L323 -> 79 | E6: ='Mechanical'!L369 -> 94
B7: Theory Questions | C7: ='Civil'!M267 -> 971 | D7: ='Other'!M323 -> 1202 | E7: ='Mechanical'!M369 -> 1770
B8: Numericals | C8: ='Civil'!N267 -> 378 | D8: ='Other'!N323 -> 691 | E8: ='Mechanical'!N369 -> 844
B9: Vid Explanation | C9: ='Civil'!O267 -> 16 | D9: ='Other'!O323 -> 26 | E9: ='Mechanical'!O369 -> 30
B10: Homework/Solution | C10: ='Civil'!P267 -> 29 | D10: ='Other'!P323 -> 43 | E10: ='Mechanical'!P369 -> 50
B11: Sample Test with Solutions | C11: Yes | D11: Yes | E11: Yes

Sheet Electrical and Computer
A1: ENGG.tv Contents
A3: Subject | B3: Chapters | C3: Topics | D3: Video Notes | E3: Solved Examples | F3: Vid Explanation | G3: Homework/Solution
A4: Mathematics | B4: Math Basics | C4: Logarithms | D4: 0 | E4: 3 | F4: 0 | G4: 1
C5: Areas and Volumes | D5: 0 | E5: 3 | F5: 0 | G5: 0
C6: Calculators | D6: 0 | E6: 2 | F6: 0 | G6: 0
B7: Algebra and Trigonometry | C7: Algebraic Equations and Roots | D7: 0 | E7: 4 | F7: 0 | G7: 0
C8: Trigonometry | D8: 3 | E8: 2 | F8: 0 | G8: 0
B9: Complex Numbers | C9: Theory of Complex Numbers | D9: 0 | E9: 2 | F9: 0 | G9: 0
C10: Different Forms of Complex Numbers | D10: 0 | E10: 2 | F10: 0 | G10: 1
C11: Algebraic Operations on Complex Numbers | D11: 1 | E11: 1 | F11: 0 | G11: 0
C12: De Moiver’s Theorem | D12: 0 | E12: 2 | F12: 0 | G12: 0
C13: Roots of Complex Number | D13: 0 | E13: 2 | F13: 0 | G13: 1
B14: Discrete Mathematics | C14: Terminology and Symbols | D14: 0 | E14: 3 | F14: 0 | G14: 0
C15: Matrix of Relations | D15: 0 | E15: 1 | F15: 0 | G15: 0
C16: Diagraph | D16: 0 | E16: 1 | F16: 0 | G16: 0
B17: Analytic Geometry | C17: Straight Lines | D17: 1 | E17: 8 | F17: 3 | G17: 1
C18: Conics | D18: 3 | E18: 3 | F18: 0 | G18: 0
C19: Circles | D19: 2 | E19: 15 | F19: 2 | G19: 1
C20: Ellipse | D20: 1 | E20: 9 | F20: 1 | G20: 1
C21: Parabola | D21: 1 | E21: 10 | F21: 0 | G21: 1
C22: Hyperbola | D22: 1 | E22: 6 | F22: 1 | G22: 1
C23: Distance Formula | D23: 0 | E23: 2 | F23: 0 | G23: 1
B24: Calculus | C24: Limits | D24: 1 | E24: 14 | F24: 1 | G24: 1
C25: Derivative | D25: 1 | E25: 4 | F25: 0 | G25: 1
C26: Application of Derivatives | D26: 2 | E26: 3 | F26: 0 | G26: 1
C27: Partial Derivatives | D27: 0 | E27: 4 | F27: 1 | G27: 1
C28: Indefinite Integrals | D28: 0 | E28: 3 | F28: 0 | G28: 0
C29: Partial Fractions | D29: 1 | E29: 2 | F29: 0 | G29: 0
C30: Trigonometric Functions | D30: 0 | E30: 2 | F30: 0 | G30: 1
C31: Definite Integrals | D31: 1 | E31: 5 | F31: 0 | G31: 1
B32: Ordinary Differential Equations | C32: General Terminology | D32: 1 | E32: 3 | F32: 0 | G32: 0
C33: First Order DE | D33: 1 | E33: 10 | F33: 0 | G33: 0
C34: Second Order Homogeneous DE | D34: 2 | E34: 3 | F34: 1 | G34: 0
C35: Finding Differential Equation from Solution | D35: 0 | E35: 7 | F35: 0 | G35: 0
C36: Applying Boundary Conditions | D36: 0 | E36: 11 | F36: 1 | G36: 0
C37: Laplace Transform | D37: 1 | E37: 10 | F37: 1 | G37: 1
B38: Linear Algebra | C38: Types of Matrices | D38: 1 | E38: 2 | F38: 0 | G38: 0
C39: Determinant of a Matrix | D39: 0 | E39: 1 | F39: 0 | G39: 0
C40: Matrix Operations | D40: 0 | E40: 8 | F40: 0 | G40: 0
B41: Vector Analysis | C41: Unit Vector | D41: 1 | E41: 2 | F41: 0 | G41: 0
...

Sheet Chemical
A1: ENGG.tv Contents
A3: Subject | B3: Chapters | C3: Topics | D3: Video Notes | E3: Solved Examples | F3: Vid Explanation | G3: Homework/Solution
A4: Mathematics | B4: Analytic Geometry | C4: Straight Lines | D4: 1 | E4: 13 | F4: 3 | G4: 1
C5: Conics | D5: 0 | E5: 3 | F5: 0 | G5: 0
C6: Circles | D6: 2 | E6: 15 | F6: 2 | G6: 1
C7: Ellipse | D7: 1 | E7: 9 | F7: 1 | G7: 1
C8: Parabola | D8: 1 | E8: 10 | F8: 0 | G8: 1
C9: Hyperbola | D9: 1 | E9: 6 | F9: 1 | G9: 1
C10: Distance Formula | D10: 0 | E10: 2 | F10: 0 | G10: 1
B11: Calculus | C11: Limits | D11: 0 | E11: 14 | F11: 1 | G11: 1
C12: Derivative | D12: 1 | E12: 4 | F12: 0 | G12: 1
C13: Application of Derivatives | D13: 0 | E13: 3 | F13: 0 | G13: 1
C14: Partial Derivatives | D14: 0 | E14: 4 | F14: 1 | G14: 1
C15: Indefinite Integrals | D15: 0 | E15: 3 | F15: 0 | G15: 0
C16: Partial Fractions | D16: 1 | E16: 2 | F16: 0 | G16: 0
C17: Trigonometric Functions | D17: 0 | E17: 2 | F17: 0 | G17: 1
C18: Definite Integrals | D18: 1 | E18: 5 | F18: 0 | G18: 1
B19: Differential Equations | C19: General Terminology | D19: 1 | E19: 3 | F19: 0 | G19: 0
C20: First Order DE | D20: 1 | E20: 10 | F20: 0 | G20: 0
C21: Second Order Homogeneous DE | D21: 2 | E21: 3 | F21: 1 | G21: 0
C22: Finding Differential Equation from Solution | D22: 0 | E22: 7 | F22: 0 | G22: 0
C23: Applying Boundary Conditions | D23: 0 | E23: 11 | F23: 1 | G23: 0
C24: Laplace Transform | D24: 1 | E24: 10 | F24: 1 | G24: 1
B25: Linear Algebra | C25: Types of Matrices | D25: 0 | E25: 2 | F25: 0 | G25: 0
C26: Determinant of a Matrix | D26: 0 | E26: 1 | F26: 0 | G26: 0
C27: Matrix Operations | D27: 0 | E27: 8 | F27: 0 | G27: 0
C28: Unit Vector | D28: 0 | E28: 2 | F28: 0 | G28: 0
C29: Addition and Subtraction of Vectors | D29: 0 | E29: 1 | F29: 0 | G29: 0
C30: Dot and Cross Products | D30: 2 | E30: 10 | F30: 1 | G30: 0
C31: Gradient, Divergence and Curl | D31: 1 | E31: 14 | F31: 0 | G31: 1
B32: Numerical Methods | C32: Newton’s Method of Root Extraction | D32: 0 | E32: 4 | F32: 0 | G32: 1
C33: Newton’s Method of Minimization | D33: 0 | E33: 2 | F33: 0 | G33: 0
C34: Forward Rectangle Rule | D34: 0 | E34: 1 | F34: 0 | G34: 1
C35: Trapezoidal Rule | D35: 1 | E35: 5 | F35: 1 | G35: 1
C36: Simpson’s Rule | D36: 0 | E36: 2 | F36: 0 | G36: 0
C37: Taylor’s and McLaurin’s Series | D37: 0 | E37: 2 | F37: 0 | G37: 1
B38: Algorithm and Logic Development | C38: Flowchart | D38: 1 | E38: 1 | F38: 0 | G38: 1
C39: Key Terms in Flowchart and Programming | D39: 0 | E39: 5 | F39: 0 | G39: 0
C40: Pseudocode | D40: 0 | E40: 5 | F40: 0 | G40: 0
A41: Probability and Statistics | B41: Probability Distributions | C41: Probability- Basic Concepts | D41: 2 | E41: 8 | F41: 0 | G41: 1
...

Sheet Industrial
A1: ENGG.tv Contents
A3: Subject | B3: Chapters | C3: Topics | D3: Video Notes | E3: Solved Examples | F3: Vid Explanation | G3: Homework/Solution
A4: Mathematics | B4: Math Basics | C4: Trigonometry | D4: 2 | E4: 6 | F4: 0 | G4: 2
C5: Logarithms | D5: 0 | E5: 1 | F5: 0 | G5: 3
C6: Theory of Complex Numbers | D6: 0 | E6: 1 | F6: 0 | G6: 2
C7: Calculators | D7: 0 | E7: 0 | F7: 0 | G7: 0
B8: Analytic Geometry | C8: Straight Lines | D8: 1 | E8: 13 | F8: 3 | G8: 1
C9: Conics | D9: 3 | E9: 3 | F9: 0 | G9: 0
C10: Circles | D10: 2 | E10: 15 | F10: 2 | G10: 1
C11: Ellipse | D11: 1 | E11: 9 | F11: 1 | G11: 1
C12: Parabola | D12: 1 | E12: 10 | F12: 0 | G12: 1
C13: Hyperbola | D13: 1 | E13: 6 | F13: 1 | G13: 1
C14: Distance Formula | D14: 0 | E14: 2 | F14: 0 | G14: 1
C15: Area and Volumes | D15: 0 | E15: 3 | F15: 0 | G15: 0
B16: Calculus | C16: Limits | D16: 0 | E16: 14 | F16: 1 | G16: 1
C17: Derivative | D17: 1 | E17: 4 | F17: 0 | G17: 1
C18: Application of Derivatives | D18: 2 | E18: 3 | F18: 0 | G18: 1
C19: Partial Derivatives | D19: 0 | E19: 4 | F19: 1 | G19: 1
C20: Indefinite Integrals | D20: 0 | E20: 3 | F20: 0 | G20: 0
C21: Partial Fractions | D21: 1 | E21: 2 | F21: 0 | G21: 0
C22: Definite Integrals | D22: 1 | E22: 5 | F22: 0 | G22: 1
C23: Progressions | D23: 0 | E23: 6 | F23: 0 | G23: 1
C24: Series | D24: 0 | E24: 2 | F24: 0 | G24: 0
B25: Linear Algebra | C25: Types of Matrices | D25: 0 | E25: 2 | F25: 0 | G25: 0
C26: Determinant of a Matrix | D26: 0 | E26: 1 | F26: 0 | G26: 0
C27: Matrix Operations | D27: 0 | E27: 8 | F27: 0 | G27: 0
C28: Unit Vector | D28: 0 | E28: 2 | F28: 0 | G28: 0
C29: Addition and Subtraction of Vectors | D29: 0 | E29: 1 | F29: 0 | G29: 0
C30: Dot and Cross Products | D30: 2 | E30: 10 | F30: 1 | G30: 0
C31: Gradient, Divergence and Curl | D31: 1 | E31: 14 | F31: 0 | G31: 1
B32: Thermodynamics | C32: Thermodynamic Properties
C33: Ideal Gas Laws
C34: Zeroth Law
C35: First Law
C36: Second Law
C37: Third Law
C38: Thermodynamic Processes
C39: Isochoric Processes
C40: Isobaric Processes
C41: Adiabatic Processes
...

Sheet Environmental
A1: ENGG.tv Contents
A3: Subject | B3: Chapters | C3: Topics | D3: Video Notes | E3: Solved Examples | F3: Vid Explanation | G3: Homework/Solution
A4: Mathematics | B4: Analytic Geometry and Trigonometry | C4: Straight Lines | D4: 1 | E4: 13 | F4: 3 | G4: 1
C5: Conics | D5: 0 | E5: 3 | F5: 0 | G5: 0
C6: Circles | D6: 2 | E6: 15 | F6: 2 | G6: 1
C7: Ellipse | D7: 1 | E7: 9 | F7: 1 | G7: 1
C8: Parabola | D8: 1 | E8: 10 | F8: 0 | G8: 1
C9: Hyperbola | D9: 1 | E9: 6 | F9: 1 | G9: 1
C10: Distance Formula | D10: 0 | E10: 2 | F10: 0 | G10: 1
C11: Trigonometry | D11: 0 | E11: 2 | F11: 0 | G11: 0
B12: Algebraic Equations and Roots | C12: Algebraic Equations and Roots | D12: 0 | E12: 4 | F12: 0 | G12: 0
C13: Newton’s Method of Root Extraction | D13: 0 | E13: 4 | F13: 0 | G13: 1
B14: Calculus | C14: Limits | D14: 0 | E14: 14 | F14: 1 | G14: 1
C15: Derivative | D15: 1 | E15: 4 | F15: 0 | G15: 1
C16: Application of Derivatives | D16: 0 | E16: 3 | F16: 0 | G16: 1
C17: Partial Derivatives | D17: 0 | E17: 4 | F17: 1 | G17: 1
C18: Indefinite Integrals | D18: 0 | E18: 3 | F18: 0 | G18: 0
C19: Partial Fractions | D19: 1 | E19: 2 | F19: 0 | G19: 0
C20: Trigonometric Functions | D20: 0 | E20: 2 | F20: 0 | G20: 1
C21: Definite Integrals | D21: 1 | E21: 5 | F21: 0 | G21: 1
B22: Numerical Methods | C22: Forward Rectangle Rule | D22: 0 | E22: 1 | F22: 0 | G22: 1
C23: Trapezoidal Rule | D23: 1 | E23: 5 | F23: 1 | G23: 1
C24: Simpson’s Rule | D24: 0 | E24: 2 | F24: 0 | G24: 0
C25: Taylor’s and McLaurin’s Series | D25: 0 | E25: 2 | F25: 0 | G25: 1
A26: Probability and Statistics | B26: Probability Distributions | C26: Probability- Basic Concepts | D26: 2 | E26: 8 | F26: 0 | G26: 1
C27: Binomial Distribution | D27: 1 | E27: 6 | F27: 1 | G27: 1
C28: Normal Distribution | D28: 0 | E28: 4 | F28: 0 | G28: 1
C29: Chi-squared distribution | D29: 2 | E29: 5 | F29: 0 | G29: 0
B30: Measures of Central Tendencies and Distribution | C30: Mean, Median Mode | D30: 0 | E30: 6 | F30: 0 | G30: 1
C31: Standard Deviation and Variance | D31: 0 | E31: 4 | F31: 0 | G31: 0
B32: Expected Value | C32: PDF and CDF | D32: 0 | E32: 1 | F32: 1 | G32: 0
C33: Expected Value of a Discrete Function | D33: 0 | E33: 4 | F33: 0 | G33: 0
B34: Regression, Curve Fitting, Goodness of Fit | C34: Regression and Curve Fitting | D34: 1 | E34: 8 | F34: 0 | G34: 0
B35: Hypothesis Testing | C35: t-distribution | D35: 0 | E35: 4 | F35: 0 | G35: 0
C36: ANOVA | D36: 0 | E36: 3 | F36: 0 | G36: 0
A37: Ethics and Professional Practice | B37: Codes of Ethics | C37: NCEES Model Law | D37: 0 | E37: 11 | F37: 0 | G37: 0
C38: Professional and Technical Societies | D38: 0 | E38: 1 | F38: 0 | G38: 0
C39: Ethical and Legal Considerations | D39: 0 | E39: 18 | F39: 0 | G39: 0
B40: Public Health, Safety and Welfare | C40: Public Health, Safety and Welfare in Engineering | D40: 0 | E40: 2 | F40: 0 | G40: 0
B41: Compliance with Codes, Standards and Regulations | C41: CWA
...
